<?xml version="1.0" encoding="utf-8"?>
<!-- This URDF was automatically created by SolidWorks to URDF Exporter! Originally created by Stephen Brawner (brawner@gmail.com) 
     Commit Version: 1.6.0-4-g7f85cfe  Build Version: 1.6.7995.38578
     For more information, please see http://wiki.ros.org/sw_urdf_exporter -->
<robot
  name="robot_6wheel_package">
  <gazebo reference="chasis_base_link">
   <material>Gazebo/Orange</material>
   <mu1>0.5</mu1>
   <mu2>0.5</mu2>
  </gazebo>
  <gazebo reference="wheel1_link">
     <material>Gazebo/White</material>
     <mu1>0.5</mu1>
     <mu2>0.5</mu2>
    </gazebo>
  <gazebo reference="wheel2_link">
     <material>Gazebo/White</material>
     <mu1>0.5</mu1>
     <mu2>0.5</mu2>
    </gazebo>
  <gazebo reference="wheel3_link">
     <material>Gazebo/White</material>
     <mu1>0.5</mu1>
     <mu2>0.5</mu2>
    </gazebo>
  <gazebo reference="wheel4_link">
     <material>Gazebo/White</material>
     <mu1>0.5</mu1>
     <mu2>0.5</mu2>
    </gazebo>
  <gazebo reference="wheel5_link">
     <material>Gazebo/White</material>
     <mu1>0.5</mu1>
     <mu2>0.5</mu2>
    </gazebo>
  <gazebo reference="wheel6_link">
     <material>Gazebo/White</material>
     <mu1>0.5</mu1>
     <mu2>0.5</mu2>
    </gazebo>
  <gazebo>
    <plugin filename="libgazebo_ros_diff_drive.so" name="differential_drive_controller">
        <alwaysOn>true</alwaysOn>
        <updateRate>20</updateRate>
        <leftJoint>wheel1_joint</leftJoint>
        <rightJoint>wheel4_joint</rightJoint>
        <wheelSeparation>0.204</wheelSeparation>
        <wheelDiameter>0.09</wheelDiameter>
        <torque>1</torque>
        <commandTopic>cmd_vel</commandTopic>
        <odometryTopic>odom</odometryTopic>
        <odometryFrame>odom</odometryFrame>
        <robotBaseFrame>link_chassis</robotBaseFrame>
    </plugin>
  </gazebo>

  <gazebo reference="camera_Link">
    <sensor type="ray" name="head_hokuyo_sensor">
        <pose>0 0 0 0 0 0</pose>
        <visualize>true</visualize>
        <update_rate>20</update_rate>
        <ray>
            <scan>
                <horizontal>
                    <samples>720</samples>
                    <resolution>1</resolution>
                    <min_angle>-0.7854</min_angle>
                    <max_angle>0.7854</max_angle>
                </horizontal>
            </scan>
            <range>
                <min>0.20</min>
                <max>5</max>
                <resolution>0.01</resolution>
            </range>
            <noise>
                <type>gaussian</type>
                <mean>0.0</mean>
                <stddev>0.01</stddev>
            </noise>
        </ray>
        <plugin name="gazebo_ros_head_hokuyo_controller" filename="libgazebo_ros_laser.so">
            <topicName>/laser/scan</topicName>
            <frameName>sensor_laser</frameName>
        </plugin>
    </sensor>
   </gazebo>

  <link
    name="chasis_base_link">
    <inertial>
      <origin
        xyz="0.15 0.075 -0.00582993130335166"
        rpy="0 0 0" />
      <mass
        value="3.7155783170235" />
      <inertia
        ixx="0.00771270055030406"
        ixy="-8.76827992918461E-18"
        ixz="-7.78645455459057E-20"
        iyy="0.0290967066578026"
        iyz="-1.44687258735659E-19"
        izz="0.036650978009623" />
    </inertial>
    <visual>
      <origin
        xyz="0 0 0"
        rpy="0 0 0" />
      <geometry>
        <mesh
          filename="package://robot_6wheel_package/meshes/chasis_base_link.STL" />
      </geometry>
      <material
        name="">
        <color
          rgba="0.529411764705882 0.549019607843137 0.549019607843137 1" />
      </material>
    </visual>
    <collision>
      <origin
        xyz="0 0 0"
        rpy="0 0 0" />
      <geometry>
        <mesh
          filename="package://robot_6wheel_package/meshes/chasis_base_link.STL" />
      </geometry>
    </collision>
  </link>
  <link
    name="wheel1_link">
    <inertial>
      <origin
        xyz="3.4095E-06 2.8072E-05 0.020558"
        rpy="0 0 0" />
      <mass
        value="0.78115" />
      <inertia
        ixx="0.00047604"
        ixy="-9.2939E-08"
        ixz="-2.7041E-09"
        iyy="0.00047528"
        iyz="-2.2261E-08"
        izz="0.00089314" />
    </inertial>
    <visual>
      <origin
        xyz="0 0 0"
        rpy="0 0 0" />
      <geometry>
        <mesh
          filename="package://robot_6wheel_package/meshes/wheel1_link.STL" />
      </geometry>
      <material
        name="">
        <color
          rgba="0.53725 0.34902 0.33725 1" />
      </material>
    </visual>
    <collision>
      <origin
        xyz="0 0 0"
        rpy="0 0 0" />
      <geometry>
        <mesh
          filename="package://robot_6wheel_package/meshes/wheel1_link.STL" />
      </geometry>
    </collision>
  </link>
  <joint
    name="wheel1_joint"
    type="revolute">
    <origin
      xyz="0.29 0.15725 -0.02"
      rpy="-1.5708 0 0" />
    <parent
      link="chasis_base_link" />
    <child
      link="wheel1_link" />
    <axis
      xyz="0 0 1" />
    <limit
      lower="-10000"
      upper="10000"
      effort="10000"
      velocity="10000" />
    <dynamics 
      damping="0"
      friction= "0.005" />
  </joint>
  <link
    name="wheel2_link">
    <inertial>
      <origin
        xyz="-2.8011E-05 -3.8831E-06 0.020558"
        rpy="0 0 0" />
      <mass
        value="0.78115" />
      <inertia
        ixx="0.00047529"
        ixy="-1.0561E-07"
        ixz="2.2212E-08"
        iyy="0.00047603"
        iyz="3.079E-09"
        izz="0.00089314" />
    </inertial>
    <visual>
      <origin
        xyz="0 0 0"
        rpy="0 0 0" />
      <geometry>
        <mesh
          filename="package://robot_6wheel_package/meshes/wheel2_link.STL" />
      </geometry>
      <material
        name="">
        <color
          rgba="0.53725 0.34902 0.33725 1" />
      </material>
    </visual>
    <collision>
      <origin
        xyz="0 0 0"
        rpy="0 0 0" />
      <geometry>
        <mesh
          filename="package://robot_6wheel_package/meshes/wheel2_link.STL" />
      </geometry>
    </collision>
  </link>
  <joint
    name="wheel2_joint"
    type="revolute">
    <origin
      xyz="0.15 0.15725 -0.02"
      rpy="-1.5708 0 0" />
    <parent
      link="chasis_base_link" />
    <child
      link="wheel2_link" />
    <axis
      xyz="0 0 1" />
    <dynamics 
      damping="0"
      friction= "0.005" />
    <limit
      lower="-10000"
      upper="10000"
      effort="10000"
      velocity="10000" />
    <dynamics 
      damping="0"
      friction= "0" />
  </joint>
  <link
    name="wheel3_link">
    <inertial>
      <origin
        xyz="-2.1048E-05 1.8886E-05 0.020558"
        rpy="0 0 0" />
      <mass
        value="0.78115" />
      <inertia
        ixx="0.00047562"
        ixy="3.8598E-07"
        ixz="1.6691E-08"
        iyy="0.0004757"
        iyz="-1.4977E-08"
        izz="0.00089314" />
    </inertial>
    <visual>
      <origin
        xyz="0 0 0"
        rpy="0 0 0" />
      <geometry>
        <mesh
          filename="package://robot_6wheel_package/meshes/wheel3_link.STL" />
      </geometry>
      <material
        name="">
        <color
          rgba="0.53725 0.34902 0.33725 1" />
      </material>
    </visual>
    <collision>
      <origin
        xyz="0 0 0"
        rpy="0 0 0" />
      <geometry>
        <mesh
          filename="package://robot_6wheel_package/meshes/wheel3_link.STL" />
      </geometry>
    </collision>
  </link>
  <joint
    name="wheel3_joint"
    type="revolute">
    <origin
      xyz="0.01 0.15725 -0.02"
      rpy="-1.5708 0 0" />
    <parent
      link="chasis_base_link" />
    <child
      link="wheel3_link" />
    <axis
      xyz="0 0 1" />
    <limit
      lower="-10000"
      upper="10000"
      effort="10000"
      velocity="10000" />
    <dynamics 
      damping="0"
      friction= "0.005" />
  </joint>
  <link
    name="wheel4_link">
    <inertial>
      <origin
        xyz="2.449E-05 1.414E-05 -0.011348"
        rpy="0 0 0" />
      <mass
        value="0.78115" />
      <inertia
        ixx="0.00047546"
        ixy="-3.3624E-07"
        ixz="-1.9421E-08"
        iyy="0.00047585"
        iyz="-1.1212E-08"
        izz="0.00089314" />
    </inertial>
    <visual>
      <origin
        xyz="0 0 0"
        rpy="0 0 0" />
      <geometry>
        <mesh
          filename="package://robot_6wheel_package/meshes/wheel4_link.STL" />
      </geometry>
      <material
        name="">
        <color
          rgba="0.53725 0.34902 0.33725 1" />
      </material>
    </visual>
    <collision>
      <origin
        xyz="0 0 0"
        rpy="0 0 0" />
      <geometry>
        <mesh
          filename="package://robot_6wheel_package/meshes/wheel4_link.STL" />
      </geometry>
    </collision>
  </link>
  <joint
    name="wheel4_joint"
    type="revolute">
    <origin
      xyz="0.29 -0.039156 -0.02"
      rpy="1.5708 0 0" />
    <parent
      link="chasis_base_link" />
    <child
      link="wheel4_link" />
    <axis
      xyz="0 0 1" />
    <limit
      lower="-10000"
      upper="10000"
      effort="10000"
      velocity="10000" />
    <dynamics 
      damping="0"
      friction= "0.005" />
  </joint>
  <link
    name="wheel5_link">
    <inertial>
      <origin
        xyz="-5.0954E-06 -2.7816E-05 -0.011348"
        rpy="0 0 0" />
      <mass
        value="0.78115" />
      <inertia
        ixx="0.00047602"
        ixy="-1.3762E-07"
        ixz="4.041E-09"
        iyy="0.0004753"
        iyz="2.2058E-08"
        izz="0.00089314" />
    </inertial>
    <visual>
      <origin
        xyz="0 0 0"
        rpy="0 0 0" />
      <geometry>
        <mesh
          filename="package://robot_6wheel_package/meshes/wheel5_link.STL" />
      </geometry>
      <material
        name="">
        <color
          rgba="0.53725 0.34902 0.33725 1" />
      </material>
    </visual>
    <collision>
      <origin
        xyz="0 0 0"
        rpy="0 0 0" />
      <geometry>
        <mesh
          filename="package://robot_6wheel_package/meshes/wheel5_link.STL" />
      </geometry>
    </collision>
  </link>
  <joint
    name="wheel5_joint"
    type="revolute">
    <origin
      xyz="0.15 -0.039156 -0.02"
      rpy="1.5708 0 0" />
    <parent
      link="chasis_base_link" />
    <child
      link="wheel5_link" />
    <axis
      xyz="0 0 1" />
    <limit
      lower="-10000"
      upper="10000"
      effort="10000"
      velocity="10000" />
    <dynamics 
      damping="0"
      friction= "0.005" />
  </joint>
  <link
    name="wheel6_link">
    <inertial>
      <origin
        xyz="9.5735E-06 -2.6609E-05 -0.011348"
        rpy="0 0 0" />
      <mass
        value="0.78115" />
      <inertia
        ixx="0.00047596"
        ixy="2.4735E-07"
        ixz="-7.5914E-09"
        iyy="0.00047536"
        iyz="2.1101E-08"
        izz="0.00089314" />
    </inertial>
    <visual>
      <origin
        xyz="0 0 0"
        rpy="0 0 0" />
      <geometry>
        <mesh
          filename="package://robot_6wheel_package/meshes/wheel6_link.STL" />
      </geometry>
      <material
        name="">
        <color
          rgba="0.53725 0.34902 0.33725 1" />
      </material>
    </visual>
    <collision>
      <origin
        xyz="0 0 0"
        rpy="0 0 0" />
      <geometry>
        <mesh
          filename="package://robot_6wheel_package/meshes/wheel6_link.STL" />
      </geometry>
    </collision>
  </link>
  <joint
    name="wheel6_joint"
    type="revolute">
    <origin
      xyz="0.01 -0.039156 -0.02"
      rpy="1.5708 0 0" />
    <parent
      link="chasis_base_link" />
    <child
      link="wheel6_link" />
    <axis
      xyz="0 0 1" />
    <limit
      lower="-10000"
      upper="10000"
      effort="10000"
      velocity="10000" />
    <dynamics 
      damping="0"
      friction= "0.005" />
  </joint>
  <link
    name="camera_Link">
    <inertial>
      <origin
        xyz="-0.0095879 0.01837 5.5091E-06"
        rpy="0 0 0" />
      <mass
        value="0.20262" />
      <inertia
        ixx="0.0001105"
        ixy="9.3359E-09"
        ixz="1.3216E-08"
        iyy="9.9558E-06"
        iyz="-5.5205E-12"
        izz="0.00011302" />
    </inertial>
    <visual>
      <origin
        xyz="0 0 0"
        rpy="0 0 0" />
      <geometry>
        <mesh
          filename="package://robot_6wheel_package/meshes/camera_Link.STL" />
      </geometry>
      <material
        name="">
        <color
          rgba="0.53725 0.34902 0.33725 1" />
      </material>
    </visual>
    <collision>
      <origin
        xyz="0 0 0"
        rpy="0 0 0" />
      <geometry>
        <mesh
          filename="package://robot_6wheel_package/meshes/camera_Link.STL" />
      </geometry>
    </collision>
  </link>
  <joint
    name="camera_joint"
    type="fixed">
    <origin
      xyz="0.2995 0.090625 0.0075"
      rpy="0 0 0" />
    <parent
      link="chasis_base_link" />
    <child
      link="camera_Link" />
    <axis
      xyz="0 0 0" />
  </joint>
</robot>


